[1,"\u001B[0m\u001B[1m\u001B[31merror\u001B[0m: Uncaught (in promise) Error: Project _quarto.yml validation failed.\n\nIn file _quarto.yml\n(line 11, columns 9--16) property name \u001B[34msection\u001B[39m is invalid\n10: \u001B[34m      - text: \"Archive\"\u001B[39m\n11: \u001B[34m        section: blog\u001B[39m\n           ~~~~~~~~\n12: \u001B[34m    right:\u001B[39m\n\u001B[34mâ„¹\u001B[39m The error happened in location \u001B[34mwebsite\u001B[39m:\u001B[34mnavbar\u001B[39m:\u001B[34mleft\u001B[39m:\u001B[34m1\u001B[39m:\u001B[34msection\u001B[39m.\n\n        throw new ValidationError2(errorMessage, yamlValidationErrors);\n\u001B[0m\u001B[31m              ^\u001B[0m\n    at \u001B[0m\u001B[1m\u001B[3mreadAndValidateYamlFromFile\u001B[0m (\u001B[0m\u001B[36mfile:///Applications/quarto/bin/quarto.js\u001B[0m:\u001B[0m\u001B[33m20063\u001B[0m:\u001B[0m\u001B[33m15\u001B[0m)\n    at async \u001B[0m\u001B[36mfile:///Applications/quarto/bin/quarto.js\u001B[0m:\u001B[0m\u001B[33m45521\u001B[0m:\u001B[0m\u001B[33m26\u001B[0m\n    at async \u001B[0m\u001B[1m\u001B[3mprojectContext\u001B[0m (\u001B[0m\u001B[36mfile:///Applications/quarto/bin/quarto.js\u001B[0m:\u001B[0m\u001B[33m45376\u001B[0m:\u001B[0m\u001B[33m26\u001B[0m)\n    at async \u001B[0m\u001B[1m\u001B[3mrender\u001B[0m (\u001B[0m\u001B[36mfile:///Applications/quarto/bin/quarto.js\u001B[0m:\u001B[0m\u001B[33m78999\u001B[0m:\u001B[0m\u001B[33m21\u001B[0m)\n"]
